<?xml version="1.0" encoding="utf-8"?>
<!-- =================================================================================== -->
<!-- |    This document was autogenerated by xacro from demo01_mycar.xacro             | -->
<!-- |    EDITING THIS FILE BY HAND IS NOT RECOMMENDED                                 | -->
<!-- =================================================================================== -->
<!--
    使用 xacro 优化 URDF 版的小车底盘实现：

    实现思路:
    1.将一些常量、变量封装为 xacro:property
      比如:PI 值、小车底盘半径、离地间距、车轮半径、宽度 ....
    2.使用 宏 封装驱动轮以及支撑轮实现，调用相关宏生成驱动轮与支撑轮

-->
<!-- 根标签，必须声明 xmlns:xacro -->
<robot name="my_car">
  <!-- 宏:黑色设置 -->
  <material name="black">
    <color rgba="0.0 0.0 0.0 1.0"/>
  </material>
  <!-- 离地间距 -->
  <!-- 底盘 -->
  <link name="base_footprint">
    <visual>
      <geometry>
        <sphere radius="0.001"/>
      </geometry>
    </visual>
  </link>
  <link name="base_link">
    <visual>
      <geometry>
        <cylinder length="0.07" radius="0.15"/>
      </geometry>
      <origin rpy="0 0 0" xyz="0 0 0"/>
      <material name="black">
        <color rgba="0 0 0.0 1"/>
      </material>
    </visual>
  </link>
  <joint name="base_link2base_footprint" type="fixed">
    <parent link="base_footprint"/>
    <child link="base_link"/>
    <origin xyz="0 0 0.095"/>
  </joint>
  
  <link name="support_laser_radar">
    <visual>
      <origin rpy="0.0 0.0 0.0" xyz="0.0 0.0 0.0"/>
      <geometry>
        <cylinder length="0.04" radius="0.015"/>
      </geometry>
      <material name="support_laser_radar_color">
        <color rgba="0.1 0.1 0.1 1.0"/>
      </material>
    </visual>
  </link>
  <!-- support2base_link  -->
  <joint name="support_laser_radar2base_link" type="fixed">
    <origin rpy="0.0 0.0 0.0" xyz="0.0 0.0 0.055"/>
    <parent link="base_link"/>
    <child link="support_laser_radar"/>
    <axis xyz="0.0 0.0 0.0"/>
  </joint>
  <link name="laser_radar">
    <visual>
      <origin rpy="0.0 0.0 0.0" xyz="0.0 0.0 0.0"/>
      <geometry>
        <cylinder length="{$ laser_radar_length}" radius="0.025"/>
      </geometry>
      <material name="laser_radar_color">
        <color rgba="0.7 0.7 0.7 1.0"/>
      </material>
    </visual>
  </link>
  <!-- laser_radar2support_laser_radar -->
  <joint name="laser_radar2support_laser_radar" type="continuous">
    <origin rpy="0.0 0.0 0.0" xyz="0.0 0.0 0.04"/>
    <parent link="base_link"/>
    <child link="laser_radar"/>
    <axis xyz="0.0 0.0 1"/>
  </joint>
  <!-- 支撑轮半径 -->
  <link name="1_wheel">
    <visual>
      <geometry>
        <sphere radius="0.04"/>
      </geometry>
      <origin rpy="0 0 0" xyz="0 0 0"/>
      <material name="wheel_color">
        <color rgba="0.7 0.7 0.7 1.0"/>
      </material>
    </visual>
  </link>
  <joint name="1_wheel2base_link" type="continuous">
    <parent link="base_link"/>
    <child link="1_wheel"/>
    <origin xyz="-0.14 0 -0.055"/>
    <axis xyz="1 1 0"/>
  </joint>
  <link name="2_wheel">
    <visual>
      <geometry>
        <sphere radius="0.04"/>
      </geometry>
      <origin rpy="0 0 0" xyz="0 0 0"/>
      <material name="wheel_color">
        <color rgba="0.7 0.7 0.7 1.0"/>
      </material>
    </visual>
  </link>
  <joint name="2_wheel2base_link" type="continuous">
    <parent link="base_link"/>
    <child link="2_wheel"/>
    <origin xyz="0.07 0.121244 -0.055"/>
    <axis xyz="1 1 0"/>
  </joint>
  <link name="3_wheel">
    <visual>
      <geometry>
        <sphere radius="0.04"/>
      </geometry>
      <origin rpy="0 0 0" xyz="0 0 0"/>
      <material name="wheel_color">
        <color rgba="0.7 0.7 0.7 1.0"/>
      </material>
    </visual>
  </link>
  <joint name="3_wheel2base_link" type="continuous">
    <parent link="base_link"/>
    <child link="3_wheel"/>
    <origin xyz="0.07 -0.121244 -0.055"/>
    <axis xyz="1 1 0"/>
  </joint>
</robot>